<mujoco>

<body name="torso" pos="0 -0.188 0.7">
   <joint name="base_x" type="slide" pos="0 0 -0.5" axis="1 0 0" range="-200.2854 200.714602" limited="true" />
   <joint name="base_y" type="slide" pos="0 0 -0.5" axis="0 1 0" range="-200.2854 200.714602" limited="true" />
   <!-- <joint name="base_y" type="slide" pos="0 0 -0.5" axis="0 1 0" limited="false" /> -->

    <geom name="torso" type="capsule" fromto="0 0 -0.6 0 0 0.2" size="0.1" />
    <geom name="sp1" type="capsule" fromto="-0.2 0 -0.7 0.2 0 -0.7" size="0.05" />
    <geom name="sp2" type="capsule" fromto="0 -0.2 -0.7 0 0.2 -0.7" size="0.05" />
    <joint name="r_shoulder_pan_joint" type="hinge" pos="0 0 0" axis="0 0 1" range="-2.2854 1.714602" damping="100.0" />

    <body name="r_shoulder_lift_link" pos="0.1 0 0">
        <geom name="sl" type="capsule" fromto="0 -0.1 0 0 0.1 0" size="0.1" />
        <joint name="r_shoulder_lift_joint" type="hinge" pos="0 0 0" axis="0 1 0" range="-0.5236 1.3963" damping="100.0" />

        <body name="r_upper_arm_roll_link" pos="0 0 0">
            <geom name="uar" type="capsule" fromto="-0.1 0 0 0.1 0 0" size="0.02" />
            <joint name="r_upper_arm_roll_joint" type="hinge" pos="0 0 0" axis="1 0 0" range="-3.9 0.8" damping="1" />

            <body name="r_upper_arm_link" pos="0 0 0">
                <geom name="ua" type="capsule" fromto="0 0 0 0.4 0 0" size="0.06" />

                <body name="r_elbow_flex_link" pos="0.4 0 0">
                    <geom name="ef" type="capsule" fromto="0 -0.02 0 0.0 0.02 0" size="0.06" />
                    <joint name="r_elbow_flex_joint" type="hinge" pos="0 0 0" axis="0 1 0" range="-2.3213 0" damping="10.0" />

                    <body name="r_forearm_roll_link" pos="0 0 0">
                        <geom name="fr" type="capsule" fromto="-0.1 0 0 0.1 0 0" size="0.02" />
                        <joint name="r_forearm_roll_joint" type="hinge" limited="false" pos="0 0 0" axis="1 0 0" damping="1" />

                        <body name="r_forearm_link" pos="0 0 0">
                            <geom name="fa" type="capsule" fromto="0 0 0 0.321 0 0" size="0.05" />

                            <body name="r_wrist_flex_link" pos="0.321 0 0">
                                <geom name="wf" type="capsule" fromto="0 -0.02 0 0 0.02 0" size="0.01" />
                                <joint name="r_wrist_flex_joint" type="hinge" pos="0 0 0" axis="0 1 0" range="-2.094 0" damping="1" />

                                <body name="r_wrist_roll_link" pos="0 0 0">
                                    <geom name="wr" type="capsule" fromto="-0.02 0 0 0.02 0 0" size="0.01" />
                                    <joint name="r_wrist_roll_joint" type="hinge" pos="0 0 0" limited="false" axis="1 0 0" damping="10" />

                                    <body name="r_gripper_palm_link" pos="0 0 0">
                                        
                                        <site name="gripper_pos" pos="0.1 0 0" size="0.01" />
                                        
                                        <body name="left_slide_body" pos="0.1 0.15 0">
                                            <joint name="left_slide" type="slide" pos="0 0 0" range="-0.15 0" damping="5.0" limited="true" axis="0 1 0"/>
                                            <geom name="leftbox" type="box" pos="0 0 0" size="0.1 0.01 0.03"/>
                                        </body>
                                        
                                        <geom name="backbox" type="box" size="0.01 0.15 0.03"/>
                                        
                                        
                                        <body name="right_slide_body" pos="0.1 -0.15 0">
                                            <joint name="right_slide" type="slide" pos="0 0 0" range="0 0.15" damping="5.0" limited="true" axis="0 1 0"/>
                                            <geom name="rightbox" type="box" pos="0 0 0" size="0.1 0.01 0.03"/>
                                        </body>
                                        
                                        
                                        
                                    </body>
                                </body>
                            </body>
                        </body>
                    </body>
                </body>
            </body>
        </body>
    </body>
</body>


<tendon>
    <fixed name="gripper">
        <joint joint="left_slide"  coef="0.1"/>
        <joint joint="right_slide"  coef="-0.1"/>
    </fixed>
</tendon>
<actuator>
    <motor joint="base_x" ctrlrange="-2.0 2.0" ctrllimited="true" />
    <motor joint="base_y" ctrlrange="-2.0 2.0" ctrllimited="true" />
    <motor tendon='gripper' ctrlrange="-10.0 10.0" name='gripper_actuator'/>
    <motor joint="r_shoulder_pan_joint" ctrlrange="-10.0 10.0" ctrllimited="true" />
    <motor joint="r_shoulder_lift_joint" ctrlrange="-10.0 10.0" ctrllimited="true" />
    <motor joint="r_upper_arm_roll_joint" ctrlrange="-10.0 10.0" ctrllimited="true" />
    <motor joint="r_elbow_flex_joint" ctrlrange="-10.0 10.0" ctrllimited="true" />
    <motor joint="r_forearm_roll_joint" ctrlrange="-10.0 10.0" ctrllimited="true" />
    <motor joint="r_wrist_flex_joint" ctrlrange="-10.0 10.0" ctrllimited="true" />
    <motor joint="r_wrist_roll_joint" ctrlrange="-10.0 10.0" ctrllimited="true" />
</actuator>
</mujoco>