<mujoco model="mobile_manipulation">
    <compiler inertiafromgeom="true" angle="radian" coordinate="local" />
    <!-- <option timestep="0.01" gravity="0 0 0" iterations="20" integrator="RK4" /> -->
    <custom>
      <numeric name="frame_skip" data="50" />
    </custom>
    <option timestep="0.001" gravity="0 0 0" iterations="1000" integrator="Euler" />
    <default>
        <joint armature="0.04" damping="10" limited="true" />
        <geom friction=".5 .1 .1" margin="0.002" condim="1" contype="0" conaffinity="0" />
    </default>
    <asset>
      <texture type="skybox" builtin="gradient" width="100" height="100" rgb1="1 1 1" rgb2="0 0 0" />
      <texture name="texgeom" type="cube" builtin="flat" mark="cross" width="127" height="1278" rgb1="0.8 0.6 0.4" rgb2="0.8 0.6 0.4" markrgb="1 1 1" random="0.01" />
      <texture name="texplane" type="2d" builtin="checker" rgb1="0 0 0" rgb2="0.8 0.8 0.8" width="100" height="100" />
      <material name='MatPlane' texture="texplane" shininess="1" texrepeat="30 30" specular="1"  reflectance="0.5" />
      <material name='geom' texture="texgeom" texuniform="true" />
    </asset>

  <worldbody>
    <light directional="true" cutoff="100" exponent="1" diffuse="1 1 1" specular=".1 .1 .1" pos="0 0 1.3" dir="-0 0 -1.3" />
    <geom name='floor' material="MatPlane" pos='0 0 -0.1' size='40 40 0.1' type='plane' conaffinity='1' rgba='0.8 0.9 0.8 1' condim='3' />
    <!--  ================= SWIMMER ================= /-->
    

    <body name="torso" pos="0 -0.188 0.5">
       <joint name="base_x" type="slide" pos="0 0 -0.5" axis="1 0 0" range="-200.2854 200.714602" limited="true" />
       <joint name="base_y" type="slide" pos="0 0 -0.5" axis="0 1 0" range="-200.2854 200.714602" limited="true" />
       <!-- <joint name="base_y" type="slide" pos="0 0 -0.5" axis="0 1 0" limited="false" /> -->

        <geom name="torso" type="capsule" fromto="0 0 -0.4 0 0 0.2" size="0.1" />
        <geom name="sp1" type="capsule" fromto="-0.2 0 -0.5 0.2 0 -0.5" size="0.05" />
        <geom name="sp2" type="capsule" fromto="0 -0.2 -0.5 0 0.2 -0.5" size="0.05" />
        <joint name="r_shoulder_pan_joint" type="hinge" pos="0 0 0" axis="0 0 1" range="-2.2854 1.714602" damping="100.0" />

        <body name="r_shoulder_lift_link" pos="0.1 0 0">
            <geom name="sl" type="capsule" fromto="0 -0.1 0 0 0.1 0" size="0.1" />
            <joint name="r_shoulder_lift_joint" type="hinge" pos="0 0 0" axis="0 1 0" range="-0.5236 1.3963" damping="100.0" />

            <body name="r_upper_arm_roll_link" pos="0 0 0">
                <geom name="uar" type="capsule" fromto="-0.1 0 0 0.1 0 0" size="0.02" />
                <joint name="r_upper_arm_roll_joint" type="hinge" pos="0 0 0" axis="1 0 0" range="-3.9 0.8" damping="1" />

                <body name="r_upper_arm_link" pos="0 0 0">
                    <geom name="ua" type="capsule" fromto="0 0 0 0.4 0 0" size="0.06" />

                    <body name="r_elbow_flex_link" pos="0.4 0 0">
                        <geom name="ef" type="capsule" fromto="0 -0.02 0 0.0 0.02 0" size="0.06" />
                        <joint name="r_elbow_flex_joint" type="hinge" pos="0 0 0" axis="0 1 0" range="-2.3213 0" damping="10.0" />

                        <body name="r_forearm_roll_link" pos="0 0 0">
                            <geom name="fr" type="capsule" fromto="-0.1 0 0 0.1 0 0" size="0.02" />
                            <joint name="r_forearm_roll_joint" type="hinge" limited="false" pos="0 0 0" axis="1 0 0" damping="1" />

                            <body name="r_forearm_link" pos="0 0 0">
                                <geom name="fa" type="capsule" fromto="0 0 0 0.321 0 0" size="0.05" />

                                <body name="r_wrist_flex_link" pos="0.321 0 0">
                                    <geom name="wf" type="capsule" fromto="0 -0.02 0 0 0.02 0" size="0.01" />
                                    <joint name="r_wrist_flex_joint" type="hinge" pos="0 0 0" axis="0 1 0" range="-2.094 0" damping="1" />

                                    <body name="r_wrist_roll_link" pos="0 0 0">
                                        <geom name="wr" type="capsule" fromto="-0.02 0 0 0.02 0 0" size="0.01" />
                                        <joint name="r_wrist_roll_joint" type="hinge" pos="0 0 0" limited="false" axis="1 0 0" damping="1" />

                                        <body name="r_gripper_palm_link" pos="0 0 0">
                                            <site name="gripper_pos" pos="0.1 0 0" size="0.01" />
                                            <geom name="backbox" type="box" size="0.01 0.2 0.2"/>
                                            <geom name="leftbox" type="box" pos="0.1 0.2 0" size="0.1 0.01 0.2"/>
                                            <geom name="rightbox" type="box" pos="0.1 -0.2 0" size="0.1 0.01 0.2"/>
                                        </body>
                                    </body>
                                </body>
                            </body>
                        </body>
                    </body>
                </body>
            </body>
        </body>
    </body>




  </worldbody>
  <actuator>
    <motor joint="base_x" ctrlrange="-2.0 2.0" ctrllimited="true" />
    <motor joint="base_y" ctrlrange="-2.0 2.0" ctrllimited="true" />
    <motor joint="r_shoulder_pan_joint" ctrlrange="-10.0 10.0" ctrllimited="true" />
    <motor joint="r_shoulder_lift_joint" ctrlrange="-10.0 10.0" ctrllimited="true" />
    <motor joint="r_upper_arm_roll_joint" ctrlrange="-10.0 10.0" ctrllimited="true" />
    <motor joint="r_elbow_flex_joint" ctrlrange="-10.0 10.0" ctrllimited="true" />
    <motor joint="r_forearm_roll_joint" ctrlrange="-10.0 10.0" ctrllimited="true" />
    <motor joint="r_wrist_flex_joint" ctrlrange="-10.0 10.0" ctrllimited="true" />
    <motor joint="r_wrist_roll_joint" ctrlrange="-10.0 10.0" ctrllimited="true" />
  </actuator>
</mujoco>
